Workbook
Name scale: Calculator!$C$20
Name XBig: Data!$B$44
Name XTravel: Data!$B$32
Name XTravelDouble: Data!$D$44
Name XTravelHalf: Data!$C$32
Name XYDiag: Data!$B$35
Name XYTravel: Data!$B$35
Name YBig: Data!$B$45
Name YTravel: Data!$B$33
Name YTravelDouble: Data!$D$45
Name YTravelHalf: Data!$C$33
Name ZBig: Data!$B$46
Name ZDiag: Data!#REF!
Name ZDiagBig: Data!#REF!
Name ZDiagDouble: Data!#REF!
Name ZDiagHalf: Data!#REF!
Name ZTravel: Data!#REF!
Name ZTravelDouble: Data!$D$46
Name ZTravelHalf: Data!#REF!
Name ZVertical: Data!$B$34
Name ZVerticalHalf: Data!$C$34
Name ZXDiag: Data!$B$37
Name ZYDiag: Data!$B$36
Name ZYTravel: Data!$B$36

Sheet Calculator
C1: CaliLantern Calculator | F1: V3.5
C2: All Instructions for this document are in the written PDF guide.
A4: Existing Calibration
B5: Skew
B6: Use Skew Model: | C6: None
A8: Klipper
B9: XY | C9: XZ | D9: YZ
B10: 0 | C10: 0 | D10: 0
A12: Marlin | B12: XY | C12: ZX | D12: ZY
B13: 0 | C13: 0 | D13: 0
A15: RRF | B15: S | C15: X | D15: Y | E15: Z
B16: 100 | C16: 0 | D16: 0 | E16: 0
A18: Measurements
A19: (This spreadsheet is locked to prevent accidental modification)
B20: Scale | C20: 1
B21: (if you have a larger printer, and larger tools, you can print at larger scale)
B23: Type | C23: Reading 1 | D23: Reading 2 | E23: Reading 3 | F23: Average | G23: Status
A24: 1 | B24: Outer | C24: 100 | D24: 100 | E24: 100 | F24: =Data!I2 -> 100 | G24: =Data!P2 -> 1
A25: 2 | B25: Outer | C25: 50 | D25: 50 | E25: 50 | F25: =Data!I3 -> 50 | G25: =Data!P3 -> 1
A26: 3 | B26: Inner | C26: 100 | D26: 100 | E26: 100 | F26: =Data!I4 -> 100 | G26: =Data!P4 -> 1
A27: 4 | B27: Inner | C27: 50 | D27: 50 | E27: 50 | F27: =Data!I5 -> 50 | G27: =Data!P5 -> 1
A28: 5 | B28: Outer | C28: 100 | D28: 100 | E28: 100 | F28: =Data!I6 -> 100 | G28: =Data!P6 -> 1
A29: 6 | B29: Outer | C29: 50 | D29: 50 | E29: 50 | F29: =Data!I7 -> 50 | G29: =Data!P7 -> 1
A30: 7 | B30: Inner | C30: 100 | D30: 100 | E30: 100 | F30: =Data!I8 -> 100 | G30: =Data!P8 -> 1
A31: 8 | B31: Inner | C31: 50 | D31: 50 | E31: 50 | F31: =Data!I9 -> 50 | G31: =Data!P9 -> 1
A32: 9 | B32: Outer | C32: 100 | D32: 100 | E32: 100 | F32: =Data!I12 -> 100 | G32: =Data!P12 -> 1
A33: 10 | B33: Outer | C33: 100 | D33: 100 | E33: 100 | F33: =Data!I13 -> 100 | G33: =Data!P13 -> 1
A34: 11 | B34: Outer | C34: 100 | D34: 100 | E34: 100 | F34: =Data!I14 -> 100 | G34: =Data!P14 -> 1
A35: 12 | B35: Outer | C35: 100 | D35: 100 | E35: 100 | F35: =Data!I15 -> 100 | G35: =Data!P15 -> 1
A36: 13 | B36: Outer | C36: 100 | D36: 100 | E36: 100 | F36: =Data!I16 -> 100 | G36: =Data!P16 -> 1
A37: 14 | B37: Outer | C37: 100 | D37: 100 | E37: 100 | F37: =Data!I17 -> 100 | G37: =Data!P17 -> 1
B39: 1 | C39: This measurement seems to have been taken correctly.
B40: 0.75 | C40: This measurement may have an error. Please Double-check your measurement.
B41: 0 | C41: This measurement very likely has a problem, may have been measured incorrectly.
A43: Results
A44: Score | B44: =Data!E103 -> 1000
A47: Size
B48: Error | C48: Correction
A49: X | B49: =Data!B41 -> 0 | C49: =B49*-1 -> 0
A50: Y | B50: =Data!C41 -> 0 | C50: =B50*-1 -> 0
...

Sheet Data
B1: Diagonal | C1: In/Out | D1: No. | E1: Design | F1: Read 1 | G1: Read 2 | H1: Read 3 | I1: Measured Avg | J1: Error | K1: % Error | L1: Abs. Error | M1: Mean Qual | N1: Reading Range | O1: Range Qual. | P1: Comment | Q1: Old No.
A2: X | C2: Outer | D2: 1 | E2: =XTravel -> 100 | F2: =Calculator!C24 -> 100 | G2: =Calculator!D24 -> 100 | H2: =Calculator!E24 -> 100 | I2: =AVERAGE(F2:H2) -> 100 | J2: =I2-E2 -> 0 | K2: =(I2-E2)/E2 -> 0 | L2: =ABS(E2-I2) -> 0 | M2: =IF(L2<$B$22,1,IF(L2<$C$22,0.5,0)) -> 1 | N2: =MAX(F2:H2)-MIN(F2:H2) -> 0 | O2: =IF(N2<$B$21,1,IF(N2<$C$21,0.5,0)) -> 1 | P2: =MIN(M2,O2) -> 1 | Q2: 1
C3: Outer | D3: 2 | E3: =XTravelHalf -> 50 | F3: =Calculator!C25 -> 50 | G3: =Calculator!D25 -> 50 | H3: =Calculator!E25 -> 50 | I3: =AVERAGE(F3:H3) -> 50 | J3: =I3-E3 -> 0 | K3: =(I3-E3)/E3 -> 0 | L3: =ABS(E3-I3) -> 0 | M3: =IF(L3<$B$22,1,IF(L3<$C$22,0.5,0)) -> 1 | N3: =MAX(F3:H3)-MIN(F3:H3) -> 0 | O3: =IF(N3<$B$21,1,IF(N3<$C$21,0.5,0)) -> 1 | P3: =MIN(M3,O3) -> 1 | Q3: 2
C4: Inner | D4: 3 | E4: =XTravel -> 100 | F4: =Calculator!C26 -> 100 | G4: =Calculator!D26 -> 100 | H4: =Calculator!E26 -> 100 | I4: =AVERAGE(F4:H4) -> 100 | J4: =I4-E4 -> 0 | K4: =(I4-E4)/E4 -> 0 | L4: =ABS(E4-I4) -> 0 | M4: =IF(L4<$B$22,1,IF(L4<$C$22,0.5,0)) -> 1 | N4: =MAX(F4:H4)-MIN(F4:H4) -> 0 | O4: =IF(N4<$B$21,1,IF(N4<$C$21,0.5,0)) -> 1 | P4: =MIN(M4,O4) -> 1 | Q4: 3
C5: Inner | D5: 4 | E5: =XTravelHalf -> 50 | F5: =Calculator!C27 -> 50 | G5: =Calculator!D27 -> 50 | H5: =Calculator!E27 -> 50 | I5: =AVERAGE(F5:H5) -> 50 | J5: =I5-E5 -> 0 | K5: =(I5-E5)/E5 -> 0 | L5: =ABS(E5-I5) -> 0 | M5: =IF(L5<$B$22,1,IF(L5<$C$22,0.5,0)) -> 1 | N5: =MAX(F5:H5)-MIN(F5:H5) -> 0 | O5: =IF(N5<$B$21,1,IF(N5<$C$21,0.5,0)) -> 1 | P5: =MIN(M5,O5) -> 1 | Q5: 4
A6: Y | C6: Outer | D6: 5 | E6: =YTravel -> 100 | F6: =Calculator!C28 -> 100 | G6: =Calculator!D28 -> 100 | H6: =Calculator!E28 -> 100 | I6: =AVERAGE(F6:H6) -> 100 | J6: =I6-E6 -> 0 | K6: =(I6-E6)/E6 -> 0 | L6: =ABS(E6-I6) -> 0 | M6: =IF(L6<$B$22,1,IF(L6<$C$22,0.5,0)) -> 1 | N6: =MAX(F6:H6)-MIN(F6:H6) -> 0 | O6: =IF(N6<$B$21,1,IF(N6<$C$21,0.5,0)) -> 1 | P6: =MIN(M6,O6) -> 1 | Q6: 5
C7: Outer | D7: 6 | E7: =YTravelHalf -> 50 | F7: =Calculator!C29 -> 50 | G7: =Calculator!D29 -> 50 | H7: =Calculator!E29 -> 50 | I7: =AVERAGE(F7:H7) -> 50 | J7: =I7-E7 -> 0 | K7: =(I7-E7)/E7 -> 0 | L7: =ABS(E7-I7) -> 0 | M7: =IF(L7<$B$22,1,IF(L7<$C$22,0.5,0)) -> 1 | N7: =MAX(F7:H7)-MIN(F7:H7) -> 0 | O7: =IF(N7<$B$21,1,IF(N7<$C$21,0.5,0)) -> 1 | P7: =MIN(M7,O7) -> 1 | Q7: 6
C8: Inner | D8: 7 | E8: =YTravel -> 100 | F8: =Calculator!C30 -> 100 | G8: =Calculator!D30 -> 100 | H8: =Calculator!E30 -> 100 | I8: =AVERAGE(F8:H8) -> 100 | J8: =I8-E8 -> 0 | K8: =(I8-E8)/E8 -> 0 | L8: =ABS(E8-I8) -> 0 | M8: =IF(L8<$B$22,1,IF(L8<$C$22,0.5,0)) -> 1 | N8: =MAX(F8:H8)-MIN(F8:H8) -> 0 | O8: =IF(N8<$B$21,1,IF(N8<$C$21,0.5,0)) -> 1 | P8: =MIN(M8,O8) -> 1 | Q8: 7
C9: Inner | D9: 8 | E9: =YTravelHalf -> 50 | F9: =Calculator!C31 -> 50 | G9: =Calculator!D31 -> 50 | H9: =Calculator!E31 -> 50 | I9: =AVERAGE(F9:H9) -> 50 | J9: =I9-E9 -> 0 | K9: =(I9-E9)/E9 -> 0 | L9: =ABS(E9-I9) -> 0 | M9: =IF(L9<$B$22,1,IF(L9<$C$22,0.5,0)) -> 1 | N9: =MAX(F9:H9)-MIN(F9:H9) -> 0 | O9: =IF(N9<$B$21,1,IF(N9<$C$21,0.5,0)) -> 1 | P9: =MIN(M9,O9) -> 1 | Q9: 8
A10: Z | C10: Outer | E10: =ZVertical -> 90 | F10: =ZVertical -> 90 | G10: =ZVertical -> 90 | H10: =ZVertical -> 90 | I10: =AVERAGE(F10:H10) -> 90 | J10: =I10-E10 -> 0 | K10: =(I10-E10)/E10 -> 0 | L10: =ABS(E10-I10) -> 0 | M10: =IF(L10<$B$22,1,IF(L10<$C$22,0.5,0)) -> 1 | N10: =MAX(F10:H10)-MIN(F10:H10) -> 0 | O10: =IF(N10<$B$21,1,IF(N10<$C$21,0.5,0)) -> 1 | P10: =MIN(M10,O10) -> 1 | Q10: 9
C11: Outer | E11: =ZVerticalHalf -> 45 | F11: =ZVerticalHalf -> 45 | G11: =ZVerticalHalf -> 45 | H11: =ZVerticalHalf -> 45 | I11: =AVERAGE(F11:H11) -> 45 | J11: =I11-E11 -> 0 | K11: =(I11-E11)/E11 -> 0 | L11: =ABS(E11-I11) -> 0 | M11: =IF(L11<$B$22,1,IF(L11<$C$22,0.5,0)) -> 1 | N11: =MAX(F11:H11)-MIN(F11:H11) -> 0 | O11: =IF(N11<$B$21,1,IF(N11<$C$21,0.5,0)) -> 1 | P11: =MIN(M11,O11) -> 1 | Q11: 10
A12: Skew XY | B12: A | C12: Outer | D12: 9 | E12: =XYDiag -> 100 | F12: =Calculator!C32 -> 100 | G12: =Calculator!D32 -> 100 | H12: =Calculator!E32 -> 100 | I12: =AVERAGE(F12:H12) -> 100 | J12: =I12-E12 -> 0 | K12: =(I12-E12)/E12 -> 0 | L12: =ABS(E12-I12) -> 0 | M12: =IF(L12<$B$22,1,IF(L12<$C$22,0.5,0)) -> 1 | N12: =MAX(F12:H12)-MIN(F12:H12) -> 0 | O12: =IF(N12<$B$21,1,IF(N12<$C$21,0.5,0)) -> 1 | P12: =MIN(M12,O12) -> 1 | Q12: 11
B13: B | C13: Outer | D13: 10 | E13: =XYDiag -> 100 | F13: =Calculator!C33 -> 100 | G13: =Calculator!D33 -> 100 | H13: =Calculator!E33 -> 100 | I13: =AVERAGE(F13:H13) -> 100 | J13: =I13-E13 -> 0 | K13: =(I13-E13)/E13 -> 0 | L13: =ABS(E13-I13) -> 0 | M13: =IF(L13<$B$22,1,IF(L13<$C$22,0.5,0)) -> 1 | N13: =MAX(F13:H13)-MIN(F13:H13) -> 0 | O13: =IF(N13<$B$21,1,IF(N13<$C$21,0.5,0)) -> 1 | P13: =MIN(M13,O13) -> 1 | Q13: 13
A14: Skew ZX | B14: A | C14: Outer | D14: 11 | E14: =ZXDiag -> 100 | F14: =Calculator!C34 -> 100 | G14: =Calculator!D34 -> 100 | H14: =Calculator!E34 -> 100 | I14: =AVERAGE(F14:H14) -> 100 | J14: =I14-E14 -> 0 | K14: =(I14-E14)/E14 -> 0 | L14: =ABS(E14-I14) -> 0 | M14: =IF(L14<$B$22,1,IF(L14<$C$22,0.5,0)) -> 1 | N14: =MAX(F14:H14)-MIN(F14:H14) -> 0 | O14: =IF(N14<$B$21,1,IF(N14<$C$21,0.5,0)) -> 1 | P14: =MIN(M14,O14) -> 1 | Q14: 15
B15: B | C15: Outer | D15: 12 | E15: =ZXDiag -> 100 | F15: =Calculator!C35 -> 100 | G15: =Calculator!D35 -> 100 | H15: =Calculator!E35 -> 100 | I15: =AVERAGE(F15:H15) -> 100 | J15: =I15-E15 -> 0 | K15: =(I15-E15)/E15 -> 0 | L15: =ABS(E15-I15) -> 0 | M15: =IF(L15<$B$22,1,IF(L15<$C$22,0.5,0)) -> 1 | N15: =MAX(F15:H15)-MIN(F15:H15) -> 0 | O15: =IF(N15<$B$21,1,IF(N15<$C$21,0.5,0)) -> 1 | P15: =MIN(M15,O15) -> 1 | Q15: 17
A16: Skew ZY | B16: A | C16: Outer | D16: 13 | E16: =ZYDiag -> 100 | F16: =Calculator!C36 -> 100 | G16: =Calculator!D36 -> 100 | H16: =Calculator!E36 -> 100 | I16: =AVERAGE(F16:H16) -> 100 | J16: =I16-E16 -> 0 | K16: =(I16-E16)/E16 -> 0 | L16: =ABS(E16-I16) -> 0 | M16: =IF(L16<$B$22,1,IF(L16<$C$22,0.5,0)) -> 1 | N16: =MAX(F16:H16)-MIN(F16:H16) -> 0 | O16: =IF(N16<$B$21,1,IF(N16<$C$21,0.5,0)) -> 1 | P16: =MIN(M16,O16) -> 1 | Q16: 19
B17: B | C17: Outer | D17: 14 | E17: =ZYDiag -> 100 | F17: =Calculator!C37 -> 100 | G17: =Calculator!D37 -> 100 | H17: =Calculator!E37 -> 100 | I17: =AVERAGE(F17:H17) -> 100 | J17: =I17-E17 -> 0 | K17: =(I17-E17)/E17 -> 0 | L17: =ABS(E17-I17) -> 0 | M17: =IF(L17<$B$22,1,IF(L17<$C$22,0.5,0)) -> 1 | N17: =MAX(F17:H17)-MIN(F17:H17) -> 0 | O17: =IF(N17<$B$21,1,IF(N17<$C$21,0.5,0)) -> 1 | P17: =MIN(M17,O17) -> 1 | Q17: 21
B20: OK | C20: Not OK
A21: Range | B21: 0.15 | C21: 0.5 | F21: V3 CHANGES
A22: Mean | B22: 0.8 | C22: 1.2 | F22: Shape that reduces contraction skew
F23: Remove double measurement from Z
A24: Validation List | F24: Remove vertical Z measurement. It doesn't shrink in the same way. Calculation assumes perfection
A25: Klipper | F25: Calculations validated with 10 degree skewed test object.
A26: Marlin
A27: RRF
A28: None
A30: Design Dimensions | L30: Stock Data | P30: Test Data
B31: Design | C31: Half | L31: 100 | M31: 100 | N31: 100 | P31: 99 | Q31: 98 | R31: 97
A32: X Travel | B32: =100*scale -> 100 | C32: =B32/2 -> 50 | L32: 50 | M32: 50 | N32: 50 | P32: 49 | Q32: 48 | R32: 47
A33: Y Travel | B33: =100*scale -> 100 | C33: =B33/2 -> 50 | L33: 100 | M33: 100 | N33: 100 | P33: 99.5 | Q33: 99.1 | R33: 99.21
A34: Z Vertical | B34: =90*scale -> 90 | C34: =B34/2 -> 45 | L34: 50 | M34: 50 | N34: 50 | P34: 49 | Q34: 46 | R34: 51
A35: XY Diag | B35: =100*scale -> 100 | L35: 100 | M35: 100 | N35: 100 | P35: 99.8 | Q35: 99.6 | R35: 100.1
A36: YZ Diag | B36: =100*scale -> 100 | L36: 50 | M36: 50 | N36: 50 | P36: 51 | Q36: 52 | R36: 49
A37: XZ Diag | B37: =100*scale -> 100 | L37: 100 | M37: 100 | N37: 100 | P37: 100.5 | Q37: 99.5 | R37: 99.8
L38: 50 | M38: 50 | N38: 50 | P38: 49 | Q38: 48 | R38: 47
A39: Measurement Summary | L39: 100 | M39: 100 | N39: 100 | P39: 101 | Q39: 102 | R39: 101
B40: X Error | C40: Y Error | D40: Z Error | E40: Inner | F40: Outer | L40: 100 | M40: 100 | N40: 100 | P40: 102 | Q40: 103 | R40: 101
A41: Average | B41: =AVERAGE(K2:K5) -> 0 | C41: =AVERAGE(K6:K9) -> 0 | D41: =AVERAGE(K10:K11) -> 0 | E41: =AVERAGE(K4:K5,K8:K9) -> 0 | F41: =AVERAGE(K2:K3,K6:K7) -> 0 | L41: 100 | M41: 100 | N41: 100 | P41: 99 | Q41: 101 | R41: 98
L42: 100 | M42: 100 | N42: 100 | P42: 101 | Q42: 101 | R42: 98
B43: Big | C43: Small | D43: Double Big | L43: 100 | M43: 100 | N43: 100 | P43: 97 | Q43: 102 | R43: 101
...
